<?xml version="1.0"?>
<robot name="myrobot">
    <link name="base_footprint">
        
    </link>
    
<!-- excelating base link -->
    <link name="base_link">
        <visual>
            <geometry>
                <box size= "0.4 0.3 0.1" />
            </geometry>
            <material name="black">
                <color rgba="0 0.0 0.0 1"/>
            </material>
        </visual>
    </link>

    <joint name="base_link_joint" type="fixed">
        <parent link="base_footprint"/>
        <child link="base_link"/>
        <origin xyz="0.0 0.0 0.0" rpy="0.0 0.0 0.0"/>
    </joint>

    <!-- excellating front left wheel -->
    <link name="front_wheel_left">
        <visual>
            <geometry>
                <cylinder radius="0.06" length="0.03"/>
            </geometry>
            <material name="green">
                <color rgba="0.0 1.0 0.0 1"/>
            </material>
        </visual>
    </link>

    <joint name="front_wheel_joint_left" type="continuous">
        <axis xyz="0.0 0.0 1"/>
        <parent link="base_link"/>
        <child link="front_wheel_left"/>
        <origin xyz="0.12 0.15 -0.05" rpy="-1.5708 0.0 0.0"/>
    </joint>

<!-- excelating front right wheel -->
    <link name="front_wheel_right">
        <visual>
            <geometry>
                <cylinder radius="0.06" length="0.03"/>
            </geometry>
            <material name="green">
                <color rgba="0.0 1.0 0.0 1"/>
            </material>
        </visual>
    </link>

    <joint name="front_wheel_joint_right" type="continuous">
        <axis xyz="0.0 0.0 1"/>
        <parent link="base_link"/>
        <child link="front_wheel_right"/>
        <origin xyz="0.12 -0.15 -0.05" rpy="-1.5708 0.0 0.0"/>
    </joint>

<!-- excelating rear wheel right -->
    <link name="rear_wheel_right">
        <visual>
           <geometry>
               <cylinder radius="0.06" length="0.03"/>
           </geometry>
           <material name="green">
               <color rgba="0.0 1.0 0.0 1"/>
           </material> 
        </visual>
    </link>

    <joint name="rear_right_wheel_joint" type="continuous">
        <axis xyz="0.0 0.0 1"/>
        <parent link="base_link"/>
        <child link="rear_wheel_right"/>
        <origin xyz="-0.12 -0.15 -0.05" rpy="-1.5708 0.0 0.0"/>
    </joint>

<!-- excelating rear front wheel -->
    <link name="rear_left_wheel">
        <visual>
           <geometry>
               <cylinder radius="0.06" length="0.03"/>
           </geometry>
           <material name="green">
               <color rgba="0.0 1.0 0.0 1"/>
           </material> 
        </visual>
    </link>

    <joint name="rear_left_wheel_joint" type="continuous">
        <axis xyz="0.0 0.0 1"/>
        <parent link="base_link"/>
        <child link="rear_left_wheel"/>
        <origin xyz="-0.12 0.15 -0.05" rpy="-1.5708 0.0 0.0"/>
    </joint>
<!-- excelating rplidar sensor -->
    <link name="RPlidar_base">
    <visual>
      <geometry>
       <box size= "0.05 0.05 0.05" />
      </geometry>
      <material name="blue">
        <color rgba="0 0 1 1"/>
      </material>
    </visual>
  </link>

  <joint name="RPlida_base_joint" type="fixed">
    <parent link="base_link"/>
    <child link="RPlidar_base"/>
    <origin xyz="0.0 0.0 0.05" rpy="0.0 0.0 0.0"/>
  </joint>

  <link name="RPlidar">
    <visual>
      <geometry>
       <cylinder radius="0.06" length="0.02"/>
      </geometry>
      <material name="black">
        <color rgba="0 0 0 1"/>
      </material>
    </visual>
  </link>

  <joint name="RPlidar_joint" type="fixed">
    <parent link="RPlidar_base"/>
    <child link="RPlidar"/>
    <origin xyz="0.0 0.0 0.034" rpy="0.0 0.0 0.0"/>
  </joint>


  <!-- excelating poles -->
  <link name="pole_1">
    <visual>
        <geometry>
            <cylinder radius="0.013" length="0.1"/>
        </geometry>
        <material name="green">
            <color rgba="0.0 1.0 0.0 1"/>
        </material>
    </visual>
  </link>

  <joint name="pole_1_joint" type="fixed">
    <parent link="base_link"/>
    <child link="pole_1"/>
    <origin xyz="0.13 0.1 0.1" rpy="0.0 0.0 0.0"/>
  </joint>

  <link name="pole_2">
    <visual>
        <geometry>
            <cylinder radius="0.013" length="0.1"/>
        </geometry>
        <material name="green">
            <color rgba="0.0 1.0 0.0 1"/>
        </material>
    </visual>
  </link>

  <joint name="pole_2_joint" type="fixed">
    <parent link="base_link"/>
    <child link="pole_2"/>
    <origin xyz="0.13 -0.1 0.1" rpy="0.0 0.0 0.0"/>
  </joint>

  <link name="pole_3">
    <visual>
        <geometry>
        <cylinder radius="0.013" length="0.1"/>
        </geometry>
        <material name="green">
            <color rgba="0.0 1.0 0.0 1"/>
        </material>
    </visual>
  </link>

  <joint name="pole_3_joint" type="fixed">
    <parent link="base_link"/>
    <child link="pole_3"/>
    <origin xyz="-0.13 0.1 0.1" rpy="0.0 0.0 0.0"/>
  </joint>

  <link name="pole_4">
    <visual>
        <geometry>
            <cylinder radius="0.013" length="0.1"/>
        </geometry>
        <material name="green">
            <color rgba="0.0 1.0 0.0 1"/>
        </material>
    </visual>
  </link>

  <joint name="pole_4_joint" type="fixed">
    <parent link="base_link"/>
    <child link="pole_4"/>
    <origin xyz="-0.13 -0.1 0.1" rpy="0.0 0.0 0.0"/>
  </joint>

  <!-- excelating payload surface -->

  <link name="payload_link">
    <visual>
      <geometry>
        <box size= "0.4 0.3 0.02" />
      </geometry>
      <material name="black">
        <color rgba="0.0 0.0 0.0 1.0"/>
      </material>
    </visual>
  </link>

  <joint name="payload_joint" type="fixed">
    <parent link="base_link"/>
    <child link="payload_link"/>
    <origin xyz="0.0 0.0 0.15" rpy="0.0 0.0 0.0"/>    
  </joint>

</robot>